<?xml version="1.0"?>
<robot xmlns:xacro="http://www.ros.org/wiki/xacro">

	<xacro:include filename="inertia.xacro" />

	<material name="white">
		<color rgba="1 1 1 1" />
	</material>

	<material name="black">
		<color rgba="0 0 0 1" />
	</material>

	<material name="red">
		<color rgba="1 0.3 0.1 1" />
	</material>

	<material name="orange">
		<color rgba="1 0 0 1" />
	</material>

	<link name="base_link"></link>

	<joint name="chassis_joint" type="fixed">
		<parent link="base_link" />
		<child link="chassis" />
		<origin xyz="-0.1 0 0" />
	</joint>

	<link name="chassis">
		<visual>
			<origin xyz="0.15 0 0.075" />
			<geometry>
				<box size="0.3 0.3 0.15" />
			</geometry>
			<material name="white" />
		</visual>
		<collision>
			<origin xyz="0.15 0 0.075" />
			<geometry>
				<box size="0.3 0.3 0.15" />
			</geometry>
		</collision>
		<xacro:inertial_box mass="1" x="0.3" y="0.3" z="0.15">
			<origin xyz="0.15 0 0.075" rpy="0 0 0" />
		</xacro:inertial_box>
	</link>

	<gazebo reference="chasis">
		<material>Gazebo/White</material>
	</gazebo>

	<joint name="left_wheel_joint" type="continuous">
		<parent link="base_link" />
		<child link="left_wheel" />
		<origin xyz="0 0.175 0" rpy="-${pi/2} 0 0" />
		<axis xyz="0 0 1" />
	</joint>

	<link name="left_wheel">
		<visual>
			<geometry>
				<cylinder radius="0.05" length="0.04" />
			</geometry>
			<material name="orange" />
		</visual>
		<collision>
			<geometry>
				<cylinder radius="0.05" length="0.04" />
			</geometry>
		</collision>
		<xacro:inertial_cylinder mass="0.1" length="0.04" radius="0.05">
			<origin xyz="0 0 0" rpy="0 0 0" />
		</xacro:inertial_cylinder>
	</link>

	<gazebo reference="left_wheel">
		<material>Gazebo/Orange</material>
		<!-- <mu>100</mu>
		<mu2>50</mu2> -->
	</gazebo>

	<joint name="right_wheel_joint" type="continuous">
		<parent link="base_link" />
		<child link="right_wheel" />
		<origin xyz="0 -0.175 0" rpy="${pi/2} 0 0" />
		<axis xyz="0 0 -1" />
	</joint>

	<link name="right_wheel">
		<visual>
			<geometry>
				<cylinder radius="0.05" length="0.04" />
			</geometry>
			<material name="orange" />
		</visual>
		<collision>
			<geometry>
				<cylinder radius="0.05" length="0.04" />
			</geometry>
		</collision>
		<xacro:inertial_cylinder mass="0.1" length="0.04" radius="0.05">
			<origin xyz="0 0 0" rpy="0 0 0" />
		</xacro:inertial_cylinder>
	</link>

	<gazebo reference="right_wheel">
		<material>Gazebo/Orange</material>
		<!-- <mu>100</mu>
		<mu2>50</mu2> -->
	</gazebo>

	<joint name="caster_wheel_joint" type="fixed">
		<parent link="chassis" />
		<child link="caster_wheel" />
		<origin xyz="0.24 0 0" />
	</joint>

	<link name="caster_wheel">
		<visual>
			<geometry>
				<sphere radius="0.05" />
			</geometry>
			<material name="orange" />
		</visual>
		<collision>
			<geometry>
				<sphere radius="0.05" />
			</geometry>
		</collision>
		<xacro:inertial_sphere mass="0.2" radius="0.05">
			<origin xyz="0 0 0" rpy="0 0 0" />
		</xacro:inertial_sphere>
	</link>

	<gazebo reference="caster_wheel">
		<material>Gazebo/Blue</material>
		<mu>0.001</mu>
		<mu2>0.001</mu2>
	</gazebo>

	<joint name="topbody_joint" type="fixed">
		<parent link="base_link" />
		<child link="topbody" />
		<origin xyz="0.1 0 0.15" />
	</joint>

	<link name="topbody">
		<visual>
			<origin xyz="0 0 0.15" />
			<geometry>
				<box size="0.05 0.05 0.5" />
			</geometry>
			<material name="white" />
		</visual>
		<collision>
			<origin xyz="0 0 0.15" />
			<geometry>
				<box size="0.05 0.05 0.5" />
			</geometry>
		</collision>
		<xacro:inertial_box mass="0.05" x="0.05" y="0.05" z="0.5">
			<origin xyz="0 0 0.15" rpy="0 0 0" />
		</xacro:inertial_box>
	</link>

	<gazebo reference="topbody">
		<material>Gazebo/Gray</material>
	</gazebo>

	<joint name="camera_joint" type="fixed">
		<axis xyz="0 1 0" />
		<origin xyz="0.17 0 0.5" rpy="0 ${pi/5} ${pi}" />
		<parent link="chassis" />
		<child link="camera_link" />
	</joint>

	<link name="camera_link">
		<collision>
			<origin xyz="0 0 0" rpy="0 0 0" />
			<geometry>
				<box size="0.025 0.025 0.025" />
			</geometry>
		</collision>

		<visual>
			<origin xyz="0 0 0" rpy="0 0 0" />
			<geometry>
				<box size="0.025 0.025 0.025" />
			</geometry>
			<material name="red" />
		</visual>

		<inertial>
			<mass value="1e-5" />
			<origin xyz="0 0 0" rpy="0 0 0" />
			<inertia ixx="1e-6" ixy="0" ixz="0" iyy="1e-6" iyz="0" izz="1e-6" />
		</inertial>
	</link>

	<gazebo reference="camera_link">
		<material>Gazebo/Red</material>
	</gazebo>

</robot>